<?xml version="1.0"?>
<robot name="diff_robot">


<material name="black">
    <color rgba="0 0 0 1.0"/>
</material>

<material name="grey">
    <color rgba="0.7 0.7 0.7 1.0"/>
</material>

<material name="green">
    <color rgba="0.0 0.6 0 1.0"/>
</material>

<material name="white">
    <color rgba="1 1 1 1.0"/>
</material>

<link name="base_footprint"/>

<link name="base_link">
    <inertial>
        <origin xyz="0.0 0.0 0.0" rpy="0.0 0.0 0.0"/>
        <mass value="0.1"/>
        <inertia ixx="0.001665" ixy="0.0" ixz="0.0" iyy="0.00441225" iyz="0.0" izz="0.00541625"/>
    </inertial>
    <visual>
        <geometry>  
            <box size="0.7 0.4 0.1"/> 
        </geometry>   
        <origin xyz="0.0 0.0 0.0" rpy="0.0 0.0 0.0"/> 
        <material name="green"/>
    </visual>
</link>

<link name="left_wheel">
    <inertial>
        <origin xyz="0.0 0.0 0.0" rpy="0.0 0.0 0.0"/>
        <mass value="0.8"/>
        <inertia ixx="0.00081252" ixy="0.0" ixz="0.0" iyy="0.00081252" iyz="0.0" izz="0.0015"/>
    </inertial>
    <visual>
        <geometry>
            <cylinder radius="0.1" length="0.05"/>
        </geometry>
        <origin xyz="0.0 0.0 0.0" rpy="1.57 0.0 0.0"/>
        <material name="black"/>     
    </visual>
    <collision>
        <geometry>
            <cylinder radius="0.1" length="0.05"/>
        </geometry>
        <origin xyz="0.0 0.0 0.0" rpy="1.57 0.0 0.0"/>
    </collision>
</link>

<link name="right_wheel">
    <inertial>
        <origin xyz="0.0 0.0 0.0" rpy="0.0 0.0 0.0"/>
        <mass value="0.8"/>
        <inertia ixx="0.00081252" ixy="0.0" ixz="0.0" iyy="0.00081252" iyz="0.0" izz="0.0015"/>
    </inertial>
    <visual>
        <geometry>
            <cylinder radius="0.1" length="0.05"/>
        </geometry>
        <origin xyz="0.0 0.0 0.0" rpy="1.57 0.0 0.0"/>
        <material name="black"/>     
    </visual>
    <collision>
        <geometry>
            <cylinder radius="0.1" length="0.05"/>
        </geometry>
        <origin xyz="0.0 0.0 0.0" rpy="1.57 0.0 0.0"/>
    </collision>
</link>

<link name="caster_wheel">
    <inertial>
        <origin xyz="0.0 0.0 0.0" rpy="0.0 0.0 0.0"/>
        <mass value="0.1"/>
        <inertia ixx="0.00016666" ixy="0.0" ixz="0.0" iyy="0.00016666" iyz="0.0" izz="0.00016666"/>
    </inertial>
    <visual>
        <geometry>
            <sphere radius="0.05"/>
        </geometry>
        <origin xyz="0.0 0.0 0.0" rpy="0.0 0.0 0.0"/>
        <material name="black"/>            
    </visual>
    <collision>
        <geometry>
            <sphere radius="0.05"/>
        </geometry>
        <origin xyz="0.0 0.0 0.0" rpy="0.0 0.0 0.0"/>
    </collision>
</link>

  <link name="camera_link">
    <visual>
        <geometry>      
            <cylinder radius="0.1" length="0.1"/>
        </geometry>
        <origin xyz="0.0 0.0 0.0" rpy="0.0 0.0 0.0"/>
        <material name="black"/>  
    </visual>
    <collision>
        <geometry>
            <cylinder radius="0.1" length="0.1"/>
        </geometry>
        <origin xyz="0.0 0.0 0.0" rpy="0.0 0.0 0.0"/>
    </collision>
    <inertial>
        <mass value="0.114" />
        <origin xyz="0 0 0" />
        <inertia ixx="0.001" ixy="0.0" ixz="0.0"
                 iyy="0.001" iyz="0.0"
                 izz="0.001" />
      </inertial>
</link>

    <link name="camera_optical_link">
        <inertial>
            <mass value="0" />
            <origin xyz="0 0 0" rpy="0 0 0"/>
            <inertia ixx="0" ixy="0" ixz="0" iyy="0" iyz="0" izz="0" />
        </inertial> 
    </link>


  <link name="lidar_link">
    <visual>
        <geometry>      
            <cylinder radius="0.1" length="0.05"/>
        </geometry>
        <origin xyz="0.00 0.0 0.0" rpy="0.0 0.0 0.0"/>
        <material name="white"/>  
    </visual>
    <collision>
        <geometry>
            <cylinder radius="0.05" length="0.05"/>
        </geometry>
        <origin xyz="0.0 0.0 0.0" rpy="0.0 0.0 0.0"/>
    </collision>
    <inertial>
        <mass value="0.004" />
        <origin xyz="0 0 0" />
        <inertia ixx="0.001" ixy="0.0" ixz="0.0"
                 iyy="0.001" iyz="0.0"
                 izz="0.001" />
      </inertial>
</link>


<joint name="base_joint" type="fixed">
    <parent link="base_link"/>
    <child link="base_footprint"/>
    <origin xyz="0.0 0.0 0.05" rpy="0.0 0.0 0.0"/>
</joint>

<joint name="base_lidar_joint" type="fixed">
    <parent link="base_link"/>
    <child link="lidar_link"/>
    <origin xyz="0.2 0.0 0.08" rpy="0.0 0.0 0.0"/>
</joint>

<!--https://wiki.ros.org/urdf/XML/joint-->
<joint name="camera_optical_joint" type="fixed">
    <origin xyz="0 0 0" rpy="-1.5708 0 -1.5708"/>
    <parent link="camera_link"/>
    <child link="camera_optical_link"/>
</joint>

<joint name="base_camera_joint" type="fixed">
    <parent link="base_link"/>
    <child link="camera_link"/>
    <origin xyz="0.2 0.0 0.17" rpy="0.0 0.0 0.0"/>
</joint>

<joint name="left_wheel_joint" type="continuous">
    <parent link="base_link"/>
    <child link="left_wheel"/>
    <origin xyz="-0.175 0.225 0.0" rpy="0 0.0 0.0"/>  
    <axis xyz="0.0 1.0 0.0"/>
    <dynamics damping="0.2" friction="1.0"/>
    <limit effort="100" velocity="1.0"/>
</joint>
<joint name="right_wheel_joint" type="continuous">
    <parent link="base_link"/>
    <child link="right_wheel"/>
    <origin xyz="-0.175 -0.225 0.0" rpy="0 0.0 0.0"/>  
    <axis xyz="0.0 1.0 0.0"/>
    <dynamics damping="0.2" friction="1.0"/>
    <limit effort="100" velocity="1.0"/>
</joint>

<joint name="caster_wheel_joint" type="fixed">
    <parent link="base_link"/>
    <child link="caster_wheel"/>
    <dynamics damping="0.2" friction="0.1"/>
    <origin xyz="0.2 0.0 -0.05" rpy="0.0 0.0 0.0"/>
</joint>



<gazebo>
    <plugin name="diff_drive" filename="libgazebo_ros_diff_drive.so">
        <!-- wheel info -->
        <left_joint>left_wheel_joint</left_joint>
        <right_joint>right_wheel_joint</right_joint>
        <wheel_separation>0.38</wheel_separation>
        <wheel_diameter>0.1</wheel_diameter>

        <!-- Limits -->
        <max_wheel_torque>200</max_wheel_torque>
        <max_wheel_acceleration>10.0</max_wheel_acceleration>

        <!-- Output -->
        <odometry_frame>odom</odometry_frame>
        <robot_base_frame>base_link</robot_base_frame>

        <publish_odom>true</publish_odom>
        <publish_odom_tf>true</publish_odom_tf>
        <publish_wheel_tf>true</publish_wheel_tf>
    </plugin>
</gazebo>


  <gazebo reference="lidar_link">
    <sensor name="laser" type="ray">
        <pose> 0 0 0 0 0 0 </pose>
        <visualize>true</visualize>
        <update_rate>10</update_rate>
        <ray>
            <scan>
                <horizontal>
                    <samples>720</samples>
                    <min_angle>-1.9</min_angle>
                    <max_angle>1.9</max_angle>
                </horizontal>
            </scan>
            <range>
                <min>0.1</min>
                <max>12</max>
            </range>
        </ray>
        <plugin name="laser_controller" filename="libgazebo_ros_ray_sensor.so">
            <ros>
                <argument>~/out:=scan</argument>
            </ros>
            <output_type>sensor_msgs/LaserScan</output_type>
            <frame_name>lidar_link</frame_name>
        </plugin>
    </sensor>
</gazebo>


<gazebo>
    <plugin name="diff_robot_joint_state" filename="libgazebo_ros_joint_state_publisher.so">
        <ros>
          <remapping>~/out:=joint_states</remapping>
        </ros>
        <update_rate>30</update_rate>
        <joint_name>left_wheel_joint</joint_name>
        <joint_name>right_wheel_joint</joint_name>
      </plugin>
    </gazebo>


<gazebo reference="camera_link">
    <sensor type="camera" name="camera">
        <always_on>true</always_on>
        <update_rate>15.0</update_rate>
        <camera name="camera">
            <horizontal_fov>1.46608</horizontal_fov>
            <image>
                <width>640</width>
                <height>480</height>
                <format>R8G8B8</format>
            </image>
            <distortion>
                <k1>0.0</k1>
                <k2>0.0</k2>
                <k3>0.0</k3>
                <p1>0.0</p1>
                <p2>0.0</p2>
                <center>0.5 0.5</center>
            </distortion>
        </camera>
        <plugin name="plugin_name" filename="libgazebo_ros_camera.so">
            <ros>
                <remapping>~/image_raw:=image_raw</remapping>
                <remapping>~/camera_info:=camera_info</remapping>
            </ros>
            <camera_name>camera</camera_name>
            <frame_name>camera_optical_link</frame_name>
        </plugin>
    </sensor>
</gazebo>

<gazebo reference="base_link">
    <material>Gazebo/Green</material>
</gazebo>
<gazebo reference="right_wheel">
    <material>Gazebo/Black</material>
</gazebo>
<gazebo reference="left_wheel">
    <material>Gazebo/Black</material>
</gazebo>
<gazebo reference="caster_wheel">
    <material>Gazebo/Black</material>
</gazebo>
<gazebo reference="camera_link">
    <material>Gazebo/Black</material>
</gazebo>

</robot>
